<!-- Cartpole Model
State-Space (name/joint/parameter):
- cart      slider      position (m)
- pole      hinge       angle (rad)
- cart      slider      velocity (m/s)
- pole      hinge       angular velocity (rad/s)
Actuators (name/actuator/parameter):
- cart      motor       force x (N)
- pole      motor       force x (N)
-->
<mujoco model='test_cartpole'>
  <compiler inertiafromgeom='true' coordinate='local'/>

  <custom>
    <numeric name="control_timestep" data="0.04" />
    <numeric name="three_numbers" data="1.0 2.0 3.0" />
  </custom>

  <option timestep='0.01'/>
  <option gravity="1e-5 0 -9.81" integrator="RK4" timestep="0.01"/>

  <default>
    <joint damping='0.05' solreflimit='.08 1'/>
    <geom contype='0' friction='1 0.1 0.1'/>
  </default>

  <!-- aesthetics for visualization -->
  <visual>
      <map fogstart="3" fogend="5" force="0.1" znear="0.5"/>
      <quality shadowsize="2048" offsamples="8"/>
      <global offwidth="800" offheight="800"/>
  </visual>

  <asset>
      <texture type="skybox" builtin="gradient" width="128" height="128" rgb1=".4 .6 .8" 
          rgb2="0 0 0"/>  
      <texture name="texgeom" type="cube" builtin="flat" mark="cross" width="127" height="1278" 
          rgb1="0.8 0.6 0.4" rgb2="0.8 0.6 0.4" markrgb="1 1 1" random="0.01"/>  
      <texture name="texplane" type="2d" builtin="checker" rgb1=".2 .3 .4" rgb2=".1 0.15 0.2" 
          width="512" height="512"/>  

      <material name='MatPlane' reflectance='0.3' texture="texplane" texrepeat="1 1" texuniform="true"/>
      <material name='geom' texture="texgeom" texuniform="true"/>
  </asset>

  <visual>
      <quality shadowsize="4096" offsamples="8"/>
      <map znear="0.1" force="0.05"/>
  </visual>

  <!-- rigid bodies -->
  <worldbody>
    <camera name='fixed' pos='0 -2.5 0' quat='0.707 0.707 0 0'/>

    <!-- ground plane: condim=3 means regular frictional contact -->
    <geom name='floor' pos='0 0 0' size='5 5 .125' type='plane' material="MatPlane" contype='1' condim='3'/>

    <!-- x-axis rails -->
    <geom name='rail1' type='capsule' pos='0 .07 0' quat='0.707 0 0.707 0' size='0.02 2' />
    <geom name='rail2' type='capsule' pos='0 -.07 0' quat='0.707 0 0.707 0' size='0.02 2' />

    <!-- wall: condim=3 means regular frictional contact -->
    <geom name='wall' pos='2 0 1' size='1 1 0.2' rgba="1 1 1 2" quat="0.7071 0 0.7071 0" type='box' contype='1' condim='3'/>

    <body name='cart' pos='1 0 0'>
      <camera name='cart' pos='0 -2.5 0' quat='0.707 0.707 0 0' />
      <!-- cart moves in the x-axis -->
      <joint name='slider' type='slide' limited='true' pos='0 0 0'
               axis='1 0 0' range='-1 1' />
      <!-- cart body geometry -->
      <geom name='cart' type='box' pos='0 0 0'
              size='0.2 0.1 0.05' rgba='0.7 0.7 0 1' />
      <!-- 1dof pole -->
      <body name='pole' pos='0 0 0'>
        <camera name='pole'  pos='0 -2.5 0' quat='0.707 0.707 0 0' />
        <joint name='hinge' type='hinge' pos='0 0 0' axis='0 1 0'/>
        <geom name='cpole' type='capsule' fromto='0 0 0 0 0 0.6'
                size='0.045 0.3' rgba='0 0.7 0.7 1' contype='1' condim='3'/>
        <site type='sphere' size='.01' name='tip' pos='.001 0 .6'/>
      </body>
      <!-- force sensor is on the end-effector -->
      <site name='tip sensor' type='box' pos='.001 0 .6'
              size='0.09 0.09 0.09' rgba='1.0 0.7 0 0' />
    </body>

  </worldbody>

  <!-- control inputs -->
  <actuator>
    <motor name='slide' joint='slider' gear='50' ctrllimited='true' ctrlrange='-1 1' />
    <motor name='pole_hinge' joint='hinge' gear='50' ctrllimited='true' ctrlrange='-5 5' />
  </actuator>

  <!-- sensors (force sensor -- might want torque instead?) -->
  <sensor>
    <force name="collision" site="tip sensor"/>
  </sensor>

</mujoco>